{'Package': 'python3-zope.exceptions', 'Source': 'zope.exceptions', 'Version': '4.0.8-1', 'Installed-Size': '90', 'Maintainer': 'Debian/Ubuntu Zope Team <pkg-zope-developers@lists.alioth.debian.org>', 'Architecture': 'all', 'Depends': ['python3-pkg-resources', 'python3-zope.interface', ['python3:any', '>=', '3.3.2-2~']], 'Description': 'Zope exceptions for Python 3', 'Homepage': 'http://pypi.python.org/pypi/zope.exceptions', 'Description-md5': '6659ed22b4d66ce3d4e50aa50de55f19', 'Section': 'zope', 'Priority': 'extra', 'Filename': 'pool/main/z/zope.exceptions/python3-zope.exceptions_4.0.8-1_all.deb', 'Size': '16756', 'SHA256': 'd02616488ab022872075cd3dfdd70e674d0d968a1daf6da0b8958c259e9471c9'}