{'Package': 'python-zope.exceptions', 'Source': 'zope.exceptions', 'Version': '4.0.8-1', 'Installed-Size': '93', 'Maintainer': 'Debian/Ubuntu Zope Team <pkg-zope-developers@lists.alioth.debian.org>', 'Architecture': 'all', 'Depends': ['python-pkg-resources', 'python-zope.interface', ['python:any', '<<', '2.8'], ['python:any', '>=', '2.7.5-5~']], 'Description': 'Zope exceptions for Python', 'Homepage': 'http://pypi.python.org/pypi/zope.exceptions', 'Description-md5': 'fb63650b0843d0f5986f71aa80d2082d', 'Section': 'python', 'Priority': 'extra', 'Filename': 'pool/main/z/zope.exceptions/python-zope.exceptions_4.0.8-1_all.deb', 'Size': '16712', 'SHA256': '0257f515083589b1cd3640347126ae2d29ff9c93e89cc2032315e151e27581fd'}